[2023-12-11 19:27:36,927] INFO _log() L96   127.0.0.1 - - [11/Dec/2023 19:27:36] "[33mDELETE /paciente?name=Tatiane HTTP/1.1[0m" 404 - - call_trace=C:\Users\ls960\AppData\Local\Packages\PythonSoftwareFoundation.Python.3.11_qbz5n2kfra8p0\LocalCache\local-packages\Python311\site-packages\werkzeug\_internal.py L96  
[2023-12-11 19:28:43,233] INFO _log() L96   127.0.0.1 - - [11/Dec/2023 19:28:43] "OPTIONS /paciente?name=Tatiane HTTP/1.1" 200 - - call_trace=C:\Users\ls960\AppData\Local\Packages\PythonSoftwareFoundation.Python.3.11_qbz5n2kfra8p0\LocalCache\local-packages\Python311\site-packages\werkzeug\_internal.py L96  
[2023-12-11 19:28:43,260] WARNING delete_paciente() L179  Erro ao deletar paciente 'Tatiane', Paciente não encontrado na base :/ - call_trace=C:\PUC\engenharia-de-software-main\mvp-qualidade-seguranca-sistemas-inteligentes\mvp\api\app.py L179 
[2023-12-11 19:28:43,275] INFO _log() L96   127.0.0.1 - - [11/Dec/2023 19:28:43] "[33mDELETE /paciente?name=Tatiane HTTP/1.1[0m" 404 - - call_trace=C:\Users\ls960\AppData\Local\Packages\PythonSoftwareFoundation.Python.3.11_qbz5n2kfra8p0\LocalCache\local-packages\Python311\site-packages\werkzeug\_internal.py L96  
[2023-12-11 19:29:03,425] WARNING get_pacientes() L50   Não há pacientes cadastrados na base :/ - call_trace=C:\PUC\engenharia-de-software-main\mvp-qualidade-seguranca-sistemas-inteligentes\mvp\api\app.py L50  
[2023-12-11 19:29:03,427] INFO _log() L96   127.0.0.1 - - [11/Dec/2023 19:29:03] "[33mGET /pacientes?nome=Sbarra HTTP/1.1[0m" 404 - - call_trace=C:\Users\ls960\AppData\Local\Packages\PythonSoftwareFoundation.Python.3.11_qbz5n2kfra8p0\LocalCache\local-packages\Python311\site-packages\werkzeug\_internal.py L96  
[2023-12-11 19:29:04,533] ERROR log_exception() L825  Exception on /paciente [POST] - call_trace=C:\Users\ls960\AppData\Local\Packages\PythonSoftwareFoundation.Python.3.11_qbz5n2kfra8p0\LocalCache\local-packages\Python311\site-packages\flask\app.py L825 
Traceback (most recent call last):
  File "C:\Users\ls960\AppData\Local\Packages\PythonSoftwareFoundation.Python.3.11_qbz5n2kfra8p0\LocalCache\local-packages\Python311\site-packages\flask\app.py", line 1455, in wsgi_app
    response = self.full_dispatch_request()
               ^^^^^^^^^^^^^^^^^^^^^^^^^^^^
  File "C:\Users\ls960\AppData\Local\Packages\PythonSoftwareFoundation.Python.3.11_qbz5n2kfra8p0\LocalCache\local-packages\Python311\site-packages\flask\app.py", line 869, in full_dispatch_request
    rv = self.handle_user_exception(e)
         ^^^^^^^^^^^^^^^^^^^^^^^^^^^^^
  File "C:\Users\ls960\AppData\Local\Packages\PythonSoftwareFoundation.Python.3.11_qbz5n2kfra8p0\LocalCache\local-packages\Python311\site-packages\flask_cors\extension.py", line 176, in wrapped_function
    return cors_after_request(app.make_response(f(*args, **kwargs)))
                                                ^^^^^^^^^^^^^^^^^^
  File "C:\Users\ls960\AppData\Local\Packages\PythonSoftwareFoundation.Python.3.11_qbz5n2kfra8p0\LocalCache\local-packages\Python311\site-packages\flask\app.py", line 867, in full_dispatch_request
    rv = self.dispatch_request()
         ^^^^^^^^^^^^^^^^^^^^^^^
  File "C:\Users\ls960\AppData\Local\Packages\PythonSoftwareFoundation.Python.3.11_qbz5n2kfra8p0\LocalCache\local-packages\Python311\site-packages\flask\app.py", line 852, in dispatch_request
    return self.ensure_sync(self.view_functions[rule.endpoint])(**view_args)
           ^^^^^^^^^^^^^^^^^^^^^^^^^^^^^^^^^^^^^^^^^^^^^^^^^^^^^^^^^^^^^^^^^
  File "C:\Users\ls960\AppData\Local\Packages\PythonSoftwareFoundation.Python.3.11_qbz5n2kfra8p0\LocalCache\local-packages\Python311\site-packages\flask_openapi3\scaffold.py", line 117, in view_func
    response = func(**func_kwargs)
               ^^^^^^^^^^^^^^^^^^^
  File "C:\PUC\engenharia-de-software-main\mvp-qualidade-seguranca-sistemas-inteligentes\mvp\api\app.py", line 93, in predict
    outcome=Model.preditor(modelo, form))
            ^^^^^^^^^^^^^^^^^^^^^^^^^^^^
  File "C:\PUC\engenharia-de-software-main\mvp-qualidade-seguranca-sistemas-inteligentes\mvp\api\model\modelo.py", line 29, in preditor
    diagnosis = model.predict(X_input.reshape(1, -1))
                ^^^^^^^^^^^^^^^^^^^^^^^^^^^^^^^^^^^^^
  File "C:\Users\ls960\AppData\Local\Packages\PythonSoftwareFoundation.Python.3.11_qbz5n2kfra8p0\LocalCache\local-packages\Python311\site-packages\sklearn\neighbors\_classification.py", line 234, in predict
    neigh_ind = self.kneighbors(X, return_distance=False)
                ^^^^^^^^^^^^^^^^^^^^^^^^^^^^^^^^^^^^^^^^^
  File "C:\Users\ls960\AppData\Local\Packages\PythonSoftwareFoundation.Python.3.11_qbz5n2kfra8p0\LocalCache\local-packages\Python311\site-packages\sklearn\neighbors\_base.py", line 806, in kneighbors
    X = self._validate_data(X, accept_sparse="csr", reset=False, order="C")
        ^^^^^^^^^^^^^^^^^^^^^^^^^^^^^^^^^^^^^^^^^^^^^^^^^^^^^^^^^^^^^^^^^^^
  File "C:\Users\ls960\AppData\Local\Packages\PythonSoftwareFoundation.Python.3.11_qbz5n2kfra8p0\LocalCache\local-packages\Python311\site-packages\sklearn\base.py", line 588, in _validate_data
    self._check_n_features(X, reset=reset)
  File "C:\Users\ls960\AppData\Local\Packages\PythonSoftwareFoundation.Python.3.11_qbz5n2kfra8p0\LocalCache\local-packages\Python311\site-packages\sklearn\base.py", line 389, in _check_n_features
    raise ValueError(
ValueError: X has 8 features, but KNeighborsClassifier is expecting 6 features as input.
[2023-12-11 19:29:04,551] INFO _log() L96   127.0.0.1 - - [11/Dec/2023 19:29:04] "[35m[1mPOST /paciente HTTP/1.1[0m" 500 - - call_trace=C:\Users\ls960\AppData\Local\Packages\PythonSoftwareFoundation.Python.3.11_qbz5n2kfra8p0\LocalCache\local-packages\Python311\site-packages\werkzeug\_internal.py L96  
[2023-12-11 19:49:19,863] INFO _log() L96   [31m[1mWARNING: This is a development server. Do not use it in a production deployment. Use a production WSGI server instead.[0m
 * Running on http://127.0.0.1:5000 - call_trace=C:\Users\ls960\AppData\Local\Packages\PythonSoftwareFoundation.Python.3.11_qbz5n2kfra8p0\LocalCache\local-packages\Python311\site-packages\werkzeug\_internal.py L96  
[2023-12-11 19:49:19,871] INFO _log() L96   [33mPress CTRL+C to quit[0m - call_trace=C:\Users\ls960\AppData\Local\Packages\PythonSoftwareFoundation.Python.3.11_qbz5n2kfra8p0\LocalCache\local-packages\Python311\site-packages\werkzeug\_internal.py L96  
[2023-12-11 19:49:36,866] WARNING get_pacientes() L50   Não há pacientes cadastrados na base :/ - call_trace=C:\PUC\engenharia-de-software-main\mvp-qualidade-seguranca-sistemas-inteligentes\mvp\api\app.py L50  
[2023-12-11 19:49:36,868] INFO _log() L96   127.0.0.1 - - [11/Dec/2023 19:49:36] "[33mGET /pacientes HTTP/1.1[0m" 404 - - call_trace=C:\Users\ls960\AppData\Local\Packages\PythonSoftwareFoundation.Python.3.11_qbz5n2kfra8p0\LocalCache\local-packages\Python311\site-packages\werkzeug\_internal.py L96  
[2023-12-11 19:50:00,841] WARNING get_pacientes() L50   Não há pacientes cadastrados na base :/ - call_trace=C:\PUC\engenharia-de-software-main\mvp-qualidade-seguranca-sistemas-inteligentes\mvp\api\app.py L50  
[2023-12-11 19:50:00,844] INFO _log() L96   127.0.0.1 - - [11/Dec/2023 19:50:00] "[33mGET /pacientes?nome=Tatiane%20Sousa HTTP/1.1[0m" 404 - - call_trace=C:\Users\ls960\AppData\Local\Packages\PythonSoftwareFoundation.Python.3.11_qbz5n2kfra8p0\LocalCache\local-packages\Python311\site-packages\werkzeug\_internal.py L96  
[2023-12-11 19:50:04,031] INFO _log() L96   127.0.0.1 - - [11/Dec/2023 19:50:04] "POST /paciente HTTP/1.1" 200 - - call_trace=C:\Users\ls960\AppData\Local\Packages\PythonSoftwareFoundation.Python.3.11_qbz5n2kfra8p0\LocalCache\local-packages\Python311\site-packages\werkzeug\_internal.py L96  
[2023-12-11 19:50:58,806] INFO _log() L96   127.0.0.1 - - [11/Dec/2023 19:50:58] "GET /pacientes?nome=Lucas HTTP/1.1" 200 - - call_trace=C:\Users\ls960\AppData\Local\Packages\PythonSoftwareFoundation.Python.3.11_qbz5n2kfra8p0\LocalCache\local-packages\Python311\site-packages\werkzeug\_internal.py L96  
[2023-12-11 19:51:01,537] INFO _log() L96   127.0.0.1 - - [11/Dec/2023 19:51:01] "POST /paciente HTTP/1.1" 200 - - call_trace=C:\Users\ls960\AppData\Local\Packages\PythonSoftwareFoundation.Python.3.11_qbz5n2kfra8p0\LocalCache\local-packages\Python311\site-packages\werkzeug\_internal.py L96  
[2023-12-11 19:52:39,240] INFO _log() L96   127.0.0.1 - - [11/Dec/2023 19:52:39] "GET /pacientes HTTP/1.1" 200 - - call_trace=C:\Users\ls960\AppData\Local\Packages\PythonSoftwareFoundation.Python.3.11_qbz5n2kfra8p0\LocalCache\local-packages\Python311\site-packages\werkzeug\_internal.py L96  
[2023-12-11 19:55:19,390] INFO _log() L96   127.0.0.1 - - [11/Dec/2023 19:55:19] "[32mGET / HTTP/1.1[0m" 302 - - call_trace=C:\Users\ls960\AppData\Local\Packages\PythonSoftwareFoundation.Python.3.11_qbz5n2kfra8p0\LocalCache\local-packages\Python311\site-packages\werkzeug\_internal.py L96  
[2023-12-11 19:55:19,411] INFO _log() L96   127.0.0.1 - - [11/Dec/2023 19:55:19] "[32mGET /openapi HTTP/1.1[0m" 308 - - call_trace=C:\Users\ls960\AppData\Local\Packages\PythonSoftwareFoundation.Python.3.11_qbz5n2kfra8p0\LocalCache\local-packages\Python311\site-packages\werkzeug\_internal.py L96  
[2023-12-11 19:55:19,444] INFO _log() L96   127.0.0.1 - - [11/Dec/2023 19:55:19] "GET /openapi/ HTTP/1.1" 200 - - call_trace=C:\Users\ls960\AppData\Local\Packages\PythonSoftwareFoundation.Python.3.11_qbz5n2kfra8p0\LocalCache\local-packages\Python311\site-packages\werkzeug\_internal.py L96  
[2023-12-11 19:55:20,049] INFO _log() L96   127.0.0.1 - - [11/Dec/2023 19:55:20] "[36mGET /openapi/static/images/swagger.svg HTTP/1.1[0m" 304 - - call_trace=C:\Users\ls960\AppData\Local\Packages\PythonSoftwareFoundation.Python.3.11_qbz5n2kfra8p0\LocalCache\local-packages\Python311\site-packages\werkzeug\_internal.py L96  
